<?xml version="1.0"?>
<robot name="ohmni">
	<!-- Colors -->
	<material name="black">
		<color rgba="0 0 0 1" />
	</material>
	<material name="green">
		<color rgba="0 1 0 1" />
	</material>
	<material name="red">
		<color rgba="1 0 0 1" />
	</material>
	<!-- Base link -->
	<link name="base_link">
		<inertial>
			<origin xyz="0.0 0.0 0.0" rpy="0.0 0.0 0.0" />
			<mass value="5.5" />
			<inertia ixx="0.03158" ixy="0" ixz="0" iyy="0.04418" iyz="0" izz="0.069898" />
		</inertial>
		<visual>
			<origin xyz="0 0 0" rpy="0 0 0" />
			<geometry>
				<mesh filename="meshes/base_link.STL" />
			</geometry>
			<material name="red" />
		</visual>
		<collision>
			<origin xyz="0 0 0" rpy="0 0 0" />
			<geometry>
				<mesh filename="meshes/base_link.STL" />
			</geometry>
		</collision>
	</link>
	<!-- Left wheel -->
	<link name="left_wheel_link">
		<inertial>
			<mass value="0.2" />
			<inertia ixx="0.00039792" ixy="0" ixz="0" iyy="0.00078467" iyz="0" izz="0.00039792" />
		</inertial>
		<visual>
			<geometry>
				<mesh filename="meshes/wheel_link.STL" />
			</geometry>
			<material name="black" />
		</visual>
		<collision>
			<geometry>
				<mesh filename="meshes/wheel_link.STL" />
			</geometry>
			<contact_coefficients mu="1.0" kp="10000000.0" kd="1.0" />
		</collision>
	</link>
	<joint name="left_wheel_joint" type="continuous">
		<origin xyz="0 0.165 0" rpy="0 0 0" />
		<parent link="base_link" />
		<child link="left_wheel_link" />
		<axis xyz="0 1 0" />
	</joint>
	<!-- Right wheel -->
	<link name="right_wheel_link">
		<inertial>
			<mass value="0.2" />
			<inertia ixx="0.00039792" ixy="0" ixz="0" iyy="0.00078467" iyz="0" izz="0.00039792" />
		</inertial>
		<visual>
			<geometry>
				<mesh filename="meshes/wheel_link.STL" />
			</geometry>
			<material name="black" />
		</visual>
		<collision>
			<geometry>
				<mesh filename="meshes/wheel_link.STL" />
			</geometry>
			<contact_coefficients mu="1.0" kp="10000000.0" kd="1.0" />
		</collision>
	</link>
	<joint name="right_wheel_joint" type="continuous">
		<origin xyz="0 -0.165 0" rpy="0 0 0" />
		<parent link="base_link" />
		<child link="right_wheel_link" />
		<axis xyz="0 1 0" />
	</joint>
	<!-- Caster -->
	<link name="caster_link">
		<inertial>
			<origin xyz="-0.016859 0 -0.039" rpy="0 0 0" />
			<mass value="0.12725" />
			<inertia ixx="0.00013389" ixy="-3.291E-08" ixz="-5.4328E-05" iyy="0.00016302" iyz="-4.433E-08" izz="9.9804E-05" />
		</inertial>
		<visual>
			<origin xyz="0 0 0" rpy="0 0 0" />
			<geometry>
				<mesh filename="meshes/caster_link.STL" />
			</geometry>
			<material name="green" />
		</visual>
		<collision>
			<origin xyz="0 0 0" rpy="0 0 0" />
			<geometry>
				<mesh filename="meshes/caster_link.STL" />
			</geometry>
		</collision>
	</link>
	<joint name="caster_joint" type="continuous">
		<origin xyz="-0.32849 0 0.036" rpy="0 0 0" />
		<parent link="base_link" />
		<child link="caster_link" />
		<axis xyz="0 0 1" />
	</joint>
	<!-- Caster wheel -->
	<link name="caster_wheel_link">
		<inertial>
			<origin xyz="0 7.5E-05 0" rpy="0 0 0" />
			<mass value="0.055271" />
			<inertia ixx="2.6207E-05" ixy="0" ixz="0" iyy="4.8328E-05" iyz="0" izz="2.6207E-05" />
		</inertial>
		<visual>
			<origin xyz="0 0 0" rpy="0 0 0" />
			<geometry>
				<mesh filename="meshes/caster_wheel_link.STL" />
			</geometry>
			<material name="black" />
		</visual>
		<collision>
			<origin xyz="0 0 0" rpy="0 0 0" />
			<geometry>
				<mesh filename="meshes/caster_wheel_link.STL" />
			</geometry>
		</collision>
		<contact>
			<lateral_friction value="0" />
		</contact>
	</link>
	<joint name="caster_wheel_joint" type="continuous">
		<origin xyz="-0.039059 0 -0.075" rpy="0 0 0" />
		<parent link="caster_link" />
		<child link="caster_wheel_link" />
		<axis xyz="0 1 0" />
	</joint>
	<!-- Tube -->
	<link name="tube_link">
		<inertial>
			<origin xyz="0.02 0 0.6" rpy="0 0 0" />
			<mass value="2" />
			<inertia ixx="0.2083333333" ixy="0.0" ixz="0.0" iyy="0.2083333333" iyz="0.0" izz="0.000905" />
		</inertial>
		<visual>
			<origin xyz="0 0 0" rpy="0 0 0" />
			<geometry>
				<mesh filename="meshes/tube_link.STL" />
			</geometry>
			<material name="black" />
		</visual>
		<collision>
			<origin xyz="0 0 0" rpy="0 0 0" />
			<geometry>
				<mesh filename="meshes/tube_link.STL" />
			</geometry>
		</collision>
	</link>
	<joint name="tube_joint" type="fixed">
		<origin xyz="-0.026814 0 0.083753" rpy="0 -0.18326 0" />
		<parent link="base_link" />
		<child link="tube_link" />
		<axis xyz="0 0 0" />
	</joint>
	<!-- Display -->
	<link name="display_link">
		<inertial>
			<origin xyz="0.02866 0.0042627 0.019125" rpy="0 0 0" />
			<mass value="0.3" />
			<inertia ixx="0.0015625" ixy="0" ixz="0" iyy="0.000625" iyz="0" izz="0.0010625" />
		</inertial>
		<visual>
			<origin xyz="0 0 0" rpy="0 0 0" />
			<geometry>
				<mesh filename="meshes/display_link.STL" />
			</geometry>
			<material name="green" />
		</visual>
		<collision>
			<origin xyz="0 0 0" rpy="0 0 0" />
			<geometry>
				<mesh filename="meshes/display_link.STL" />
			</geometry>
		</collision>
	</link>
	<joint name="neck_joint" type="continuous">
		<origin xyz="0.14191 0 1.1557" rpy="0 0 0" />
		<parent link="tube_link" />
		<child link="display_link" />
		<axis xyz="0 1 0" />
	</joint>
</robot>
